data/sample_replay.csv
# timestamp_ns,type,side,order_id,price,quantity,new_order_id
100,L,B,1001,10000,50,0
200,L,B,1002,9999,40,0
300,L,S,2001,10002,30,0
400,L,S,2002,10001,20,0
500,M,B,3001,0,15,0
600,U,B,1001,0,25,0
700,R,S,2001,10003,25,2003
800,L,S,2004,10000,60,0
900,L,B,1003,10001,70,0
1000,C,B,1002,0,0,0
1100,M,S,3002,0,20,0
